<?xml version="1.0" encoding="UTF-8"?>
<robot generator="Robot 3.1.1 (Python 3.7.2 on win32)" generated="20190521 14:32:29.921" rpa="false">
<suite id="s1" name="apiTestCases" source="C:\Project\robotframework\tests\apiTestCases.robot">
<test id="s1-t1" name="BookApiTestCases">
<kw name="BookGetAndPutRequest" library="TrendyolApiFacilities">
<kw name="ListEmptyGetRequest" library="TrendyolApiFacilities">
<kw name="GetAllBookList" library="TrendyolApiFacilities">
<assign>
<var>${resp}</var>
</assign>
<kw name="Create Session" library="ExtendedRequestsLibrary">
<doc>Create and return a HTTP session object to a server.</doc>
<arguments>
<arg>httpbin</arg>
<arg>${apiURL}</arg>
</arguments>
<msg timestamp="20190521 14:32:30.472" level="INFO">Creating Session using : alias=httpbin, url=http://foobarBookApi.com, headers={},                     cookies=None, auth=None, timeout=None, proxies=None, verify=False,                     debug=0 </msg>
<status status="PASS" starttime="20190521 14:32:30.472" endtime="20190521 14:32:30.472"></status>
</kw>
<kw name="Get Request" library="ExtendedRequestsLibrary">
<doc>Send a GET request on the session object found in the cache using the given ``label``.</doc>
<arguments>
<arg>httpbin</arg>
<arg>${apiPath}</arg>
</arguments>
<assign>
<var>${resp}</var>
</assign>
<msg timestamp="20190521 14:32:30.573" level="WARN">Retrying (Retry(total=2, connect=None, read=None, redirect=None, status=None)) after connection broken by 'NewConnectionError('&lt;urllib3.connection.HTTPConnection object at 0x000002AAA36E55C0&gt;: Failed to establish a new connection: [Errno 11001] getaddrinfo failed')': /api/book</msg>
<msg timestamp="20190521 14:32:30.776" level="WARN">Retrying (Retry(total=1, connect=None, read=None, redirect=None, status=None)) after connection broken by 'NewConnectionError('&lt;urllib3.connection.HTTPConnection object at 0x000002AAA36E5940&gt;: Failed to establish a new connection: [Errno 11001] getaddrinfo failed')': /api/book</msg>
<msg timestamp="20190521 14:32:31.177" level="WARN">Retrying (Retry(total=0, connect=None, read=None, redirect=None, status=None)) after connection broken by 'NewConnectionError('&lt;urllib3.connection.HTTPConnection object at 0x000002AAA36DCF28&gt;: Failed to establish a new connection: [Errno 11001] getaddrinfo failed')': /api/book</msg>
<msg timestamp="20190521 14:32:31.220" level="FAIL">ConnectionError: HTTPConnectionPool(host='foobarbookapi.com', port=80): Max retries exceeded with url: /api/book (Caused by NewConnectionError('&lt;urllib3.connection.HTTPConnection object at 0x000002AAA36DCDD8&gt;: Failed to establish a new connection: [Errno 11001] getaddrinfo failed'))</msg>
<status status="FAIL" starttime="20190521 14:32:30.472" endtime="20190521 14:32:31.220"></status>
</kw>
<status status="FAIL" starttime="20190521 14:32:30.471" endtime="20190521 14:32:31.220"></status>
</kw>
<status status="FAIL" starttime="20190521 14:32:30.471" endtime="20190521 14:32:31.220"></status>
</kw>
<status status="FAIL" starttime="20190521 14:32:30.471" endtime="20190521 14:32:31.220"></status>
</kw>
<status status="FAIL" starttime="20190521 14:32:30.470" endtime="20190521 14:32:31.220" critical="yes">ConnectionError: HTTPConnectionPool(host='foobarbookapi.com', port=80): Max retries exceeded with url: /api/book (Caused by NewConnectionError('&lt;urllib3.connection.HTTPConnection object at 0x000002AAA36DCDD8&gt;: Failed to establish a new connection: [Errno 11001] getaddrinfo failed'))</status>
</test>
<status status="FAIL" starttime="20190521 14:32:29.922" endtime="20190521 14:32:31.221"></status>
</suite>
<statistics>
<total>
<stat pass="0" fail="1">Critical Tests</stat>
<stat pass="0" fail="1">All Tests</stat>
</total>
<tag>
</tag>
<suite>
<stat pass="0" fail="1" id="s1" name="apiTestCases">apiTestCases</stat>
</suite>
</statistics>
<errors>
<msg timestamp="20190521 14:32:30.573" level="WARN">Retrying (Retry(total=2, connect=None, read=None, redirect=None, status=None)) after connection broken by 'NewConnectionError('&lt;urllib3.connection.HTTPConnection object at 0x000002AAA36E55C0&gt;: Failed to establish a new connection: [Errno 11001] getaddrinfo failed')': /api/book</msg>
<msg timestamp="20190521 14:32:30.776" level="WARN">Retrying (Retry(total=1, connect=None, read=None, redirect=None, status=None)) after connection broken by 'NewConnectionError('&lt;urllib3.connection.HTTPConnection object at 0x000002AAA36E5940&gt;: Failed to establish a new connection: [Errno 11001] getaddrinfo failed')': /api/book</msg>
<msg timestamp="20190521 14:32:31.177" level="WARN">Retrying (Retry(total=0, connect=None, read=None, redirect=None, status=None)) after connection broken by 'NewConnectionError('&lt;urllib3.connection.HTTPConnection object at 0x000002AAA36DCF28&gt;: Failed to establish a new connection: [Errno 11001] getaddrinfo failed')': /api/book</msg>
</errors>
</robot>
